[2023-06-29T09:35:49.452+0000] {logging_mixin.py:149} INFO - Changing /opt/***/logs/dag_id=2_Test_Badge_5_Loop/run_id=scheduled__2023-06-29T09:34:00+00:00/task_id=snowflake_sensor_task permission to 509
[2023-06-29T09:35:49.452+0000] {logging_mixin.py:149} INFO - Failed to change /opt/***/logs/dag_id=2_Test_Badge_5_Loop/run_id=scheduled__2023-06-29T09:34:00+00:00/task_id=snowflake_sensor_task permission to 509: [Errno 1] Operation not permitted: '/opt/***/logs/dag_id=2_Test_Badge_5_Loop/run_id=scheduled__2023-06-29T09:34:00+00:00/task_id=snowflake_sensor_task'
[2023-06-29T09:35:49.480+0000] {logging_mixin.py:149} INFO - Changing /opt/***/logs/dag_id=2_Test_Badge_5_Loop/run_id=scheduled__2023-06-29T09:34:00+00:00/task_id=snowflake_sensor_task permission to 509
[2023-06-29T09:35:49.481+0000] {logging_mixin.py:149} INFO - Failed to change /opt/***/logs/dag_id=2_Test_Badge_5_Loop/run_id=scheduled__2023-06-29T09:34:00+00:00/task_id=snowflake_sensor_task permission to 509: [Errno 1] Operation not permitted: '/opt/***/logs/dag_id=2_Test_Badge_5_Loop/run_id=scheduled__2023-06-29T09:34:00+00:00/task_id=snowflake_sensor_task'
[2023-06-29T09:35:49.511+0000] {taskinstance.py:1103} INFO - Dependencies all met for dep_context=non-requeueable deps ti=<TaskInstance: 2_Test_Badge_5_Loop.snowflake_sensor_task scheduled__2023-06-29T09:34:00+00:00 [queued]>
[2023-06-29T09:35:49.521+0000] {taskinstance.py:1103} INFO - Dependencies all met for dep_context=requeueable deps ti=<TaskInstance: 2_Test_Badge_5_Loop.snowflake_sensor_task scheduled__2023-06-29T09:34:00+00:00 [queued]>
[2023-06-29T09:35:49.521+0000] {taskinstance.py:1308} INFO - Starting attempt 1 of 1
[2023-06-29T09:35:49.538+0000] {taskinstance.py:1327} INFO - Executing <Task(SnowflakeStreamSensor): snowflake_sensor_task> on 2023-06-29 09:34:00+00:00
[2023-06-29T09:35:49.543+0000] {standard_task_runner.py:57} INFO - Started process 3194 to run task
[2023-06-29T09:35:49.546+0000] {standard_task_runner.py:84} INFO - Running: ['***', 'tasks', 'run', '2_Test_Badge_5_Loop', 'snowflake_sensor_task', 'scheduled__2023-06-29T09:34:00+00:00', '--job-id', '623', '--raw', '--subdir', 'DAGS_FOLDER/test_loop.py', '--cfg-path', '/tmp/tmp5ha5anqd']
[2023-06-29T09:35:49.547+0000] {standard_task_runner.py:85} INFO - Job 623: Subtask snowflake_sensor_task
[2023-06-29T09:35:49.588+0000] {logging_mixin.py:149} INFO - Changing /opt/***/logs/dag_id=2_Test_Badge_5_Loop/run_id=scheduled__2023-06-29T09:34:00+00:00/task_id=snowflake_sensor_task permission to 509
[2023-06-29T09:35:49.588+0000] {logging_mixin.py:149} INFO - Failed to change /opt/***/logs/dag_id=2_Test_Badge_5_Loop/run_id=scheduled__2023-06-29T09:34:00+00:00/task_id=snowflake_sensor_task permission to 509: [Errno 1] Operation not permitted: '/opt/***/logs/dag_id=2_Test_Badge_5_Loop/run_id=scheduled__2023-06-29T09:34:00+00:00/task_id=snowflake_sensor_task'
[2023-06-29T09:35:49.590+0000] {task_command.py:410} INFO - Running <TaskInstance: 2_Test_Badge_5_Loop.snowflake_sensor_task scheduled__2023-06-29T09:34:00+00:00 [running]> on host 01bc60642780
[2023-06-29T09:35:49.670+0000] {taskinstance.py:1547} INFO - Exporting env vars: AIRFLOW_CTX_DAG_OWNER='***' AIRFLOW_CTX_DAG_ID='2_Test_Badge_5_Loop' AIRFLOW_CTX_TASK_ID='snowflake_sensor_task' AIRFLOW_CTX_EXECUTION_DATE='2023-06-29T09:34:00+00:00' AIRFLOW_CTX_TRY_NUMBER='1' AIRFLOW_CTX_DAG_RUN_ID='scheduled__2023-06-29T09:34:00+00:00'
[2023-06-29T09:35:49.671+0000] {connection.py:265} INFO - Snowflake Connector for Python Version: 2.4.5, Python Version: 3.7.16, Platform: Linux-5.15.90.1-microsoft-standard-WSL2-x86_64-with-debian-11.7
[2023-06-29T09:35:49.679+0000] {taskinstance.py:1824} ERROR - Task failed with exception
Traceback (most recent call last):
  File "/home/airflow/.local/lib/python3.7/site-packages/airflow/sensors/base.py", line 225, in execute
    raise e
  File "/home/airflow/.local/lib/python3.7/site-packages/airflow/sensors/base.py", line 212, in execute
    poke_return = self.poke(context)
  File "/opt/airflow/dags/snowflake_sensor.py", line 21, in poke
    conn = connect(conn_name=self.snowflake_connection)
  File "/home/airflow/.local/lib/python3.7/site-packages/snowflake/connector/__init__.py", line 50, in Connect
    return SnowflakeConnection(**kwargs)
  File "/home/airflow/.local/lib/python3.7/site-packages/snowflake/connector/connection.py", line 276, in __init__
    self.connect(**kwargs)
  File "/home/airflow/.local/lib/python3.7/site-packages/snowflake/connector/connection.py", line 488, in connect
    self.__config(**kwargs)
  File "/home/airflow/.local/lib/python3.7/site-packages/snowflake/connector/connection.py", line 835, in __config
    {"msg": "User is empty", "errno": ER_NO_USER},
  File "/home/airflow/.local/lib/python3.7/site-packages/snowflake/connector/errors.py", line 261, in errorhandler_wrapper
    connection.errorhandler(connection, cursor, error_class, error_value)
  File "/home/airflow/.local/lib/python3.7/site-packages/snowflake/connector/errors.py", line 195, in default_errorhandler
    cursor=cursor,
snowflake.connector.errors.ProgrammingError: 251005: 251005: User is empty
[2023-06-29T09:35:49.686+0000] {taskinstance.py:1350} INFO - Marking task as FAILED. dag_id=2_Test_Badge_5_Loop, task_id=snowflake_sensor_task, execution_date=20230629T093400, start_date=20230629T093549, end_date=20230629T093549
[2023-06-29T09:35:49.697+0000] {standard_task_runner.py:109} ERROR - Failed to execute job 623 for task snowflake_sensor_task (251005: 251005: User is empty; 3194)
[2023-06-29T09:35:49.838+0000] {local_task_job_runner.py:225} INFO - Task exited with return code 1
[2023-06-29T09:35:49.870+0000] {taskinstance.py:2651} INFO - 0 downstream tasks scheduled from follow-on schedule check
