[2023-06-27T08:42:14.987+0000] {logging_mixin.py:149} INFO - Changing /opt/***/logs/dag_id=2_Test_Badge_5_Loop/run_id=scheduled__2023-06-27T02:20:00+00:00/task_id=create_select permission to 509
[2023-06-27T08:42:14.999+0000] {logging_mixin.py:149} INFO - Failed to change /opt/***/logs/dag_id=2_Test_Badge_5_Loop/run_id=scheduled__2023-06-27T02:20:00+00:00/task_id=create_select permission to 509: [Errno 1] Operation not permitted: '/opt/***/logs/dag_id=2_Test_Badge_5_Loop/run_id=scheduled__2023-06-27T02:20:00+00:00/task_id=create_select'
[2023-06-27T08:42:15.078+0000] {logging_mixin.py:149} INFO - Changing /opt/***/logs/dag_id=2_Test_Badge_5_Loop/run_id=scheduled__2023-06-27T02:20:00+00:00/task_id=create_select permission to 509
[2023-06-27T08:42:15.086+0000] {logging_mixin.py:149} INFO - Failed to change /opt/***/logs/dag_id=2_Test_Badge_5_Loop/run_id=scheduled__2023-06-27T02:20:00+00:00/task_id=create_select permission to 509: [Errno 1] Operation not permitted: '/opt/***/logs/dag_id=2_Test_Badge_5_Loop/run_id=scheduled__2023-06-27T02:20:00+00:00/task_id=create_select'
[2023-06-27T08:42:17.106+0000] {taskinstance.py:1103} INFO - Dependencies all met for dep_context=non-requeueable deps ti=<TaskInstance: 2_Test_Badge_5_Loop.create_select scheduled__2023-06-27T02:20:00+00:00 [queued]>
[2023-06-27T08:42:17.128+0000] {taskinstance.py:1103} INFO - Dependencies all met for dep_context=requeueable deps ti=<TaskInstance: 2_Test_Badge_5_Loop.create_select scheduled__2023-06-27T02:20:00+00:00 [queued]>
[2023-06-27T08:42:17.130+0000] {taskinstance.py:1308} INFO - Starting attempt 1 of 1
[2023-06-27T08:42:17.230+0000] {taskinstance.py:1327} INFO - Executing <Task(BashOperator): create_select> on 2023-06-27 02:20:00+00:00
[2023-06-27T08:42:17.253+0000] {standard_task_runner.py:57} INFO - Started process 4485 to run task
[2023-06-27T08:42:17.275+0000] {standard_task_runner.py:84} INFO - Running: ['***', 'tasks', 'run', '2_Test_Badge_5_Loop', 'create_select', 'scheduled__2023-06-27T02:20:00+00:00', '--job-id', '168', '--raw', '--subdir', 'DAGS_FOLDER/test.py', '--cfg-path', '/tmp/tmpon2t46oo']
[2023-06-27T08:42:17.289+0000] {standard_task_runner.py:85} INFO - Job 168: Subtask create_select
[2023-06-27T08:42:17.450+0000] {logging_mixin.py:149} INFO - Changing /opt/***/logs/dag_id=2_Test_Badge_5_Loop/run_id=scheduled__2023-06-27T02:20:00+00:00/task_id=create_select permission to 509
[2023-06-27T08:42:17.451+0000] {logging_mixin.py:149} INFO - Failed to change /opt/***/logs/dag_id=2_Test_Badge_5_Loop/run_id=scheduled__2023-06-27T02:20:00+00:00/task_id=create_select permission to 509: [Errno 1] Operation not permitted: '/opt/***/logs/dag_id=2_Test_Badge_5_Loop/run_id=scheduled__2023-06-27T02:20:00+00:00/task_id=create_select'
[2023-06-27T08:42:17.456+0000] {task_command.py:410} INFO - Running <TaskInstance: 2_Test_Badge_5_Loop.create_select scheduled__2023-06-27T02:20:00+00:00 [running]> on host 4d37da440d5c
[2023-06-27T08:42:17.853+0000] {taskinstance.py:1547} INFO - Exporting env vars: AIRFLOW_CTX_DAG_OWNER='***' AIRFLOW_CTX_DAG_ID='2_Test_Badge_5_Loop' AIRFLOW_CTX_TASK_ID='create_select' AIRFLOW_CTX_EXECUTION_DATE='2023-06-27T02:20:00+00:00' AIRFLOW_CTX_TRY_NUMBER='1' AIRFLOW_CTX_DAG_RUN_ID='scheduled__2023-06-27T02:20:00+00:00'
[2023-06-27T08:42:17.859+0000] {subprocess.py:63} INFO - Tmp dir root location: 
 /tmp
[2023-06-27T08:42:17.862+0000] {subprocess.py:75} INFO - Running command: ['/bin/bash', '-c', 'cd /dbt && dbt run --model select']
[2023-06-27T08:42:17.885+0000] {subprocess.py:86} INFO - Output:
[2023-06-27T08:42:29.735+0000] {subprocess.py:93} INFO - [0m08:42:29  Running with dbt=1.5.1
[2023-06-27T08:42:51.323+0000] {job.py:216} ERROR - Job heartbeat got an exception
Traceback (most recent call last):
  File "/home/airflow/.local/lib/python3.7/site-packages/sqlalchemy/engine/base.py", line 3366, in _wrap_pool_connect
    return fn()
  File "/home/airflow/.local/lib/python3.7/site-packages/sqlalchemy/pool/base.py", line 327, in connect
    return _ConnectionFairy._checkout(self)
  File "/home/airflow/.local/lib/python3.7/site-packages/sqlalchemy/pool/base.py", line 894, in _checkout
    fairy = _ConnectionRecord.checkout(pool)
  File "/home/airflow/.local/lib/python3.7/site-packages/sqlalchemy/pool/base.py", line 493, in checkout
    rec = pool._do_get()
  File "/home/airflow/.local/lib/python3.7/site-packages/sqlalchemy/pool/impl.py", line 256, in _do_get
    return self._create_connection()
  File "/home/airflow/.local/lib/python3.7/site-packages/sqlalchemy/pool/base.py", line 273, in _create_connection
    return _ConnectionRecord(self)
  File "/home/airflow/.local/lib/python3.7/site-packages/sqlalchemy/pool/base.py", line 388, in __init__
    self.__connect()
  File "/home/airflow/.local/lib/python3.7/site-packages/sqlalchemy/pool/base.py", line 691, in __connect
    pool.logger.debug("Error on connect(): %s", e)
  File "/home/airflow/.local/lib/python3.7/site-packages/sqlalchemy/util/langhelpers.py", line 72, in __exit__
    with_traceback=exc_tb,
  File "/home/airflow/.local/lib/python3.7/site-packages/sqlalchemy/util/compat.py", line 211, in raise_
    raise exception
  File "/home/airflow/.local/lib/python3.7/site-packages/sqlalchemy/pool/base.py", line 686, in __connect
    self.dbapi_connection = connection = pool._invoke_creator(self)
  File "/home/airflow/.local/lib/python3.7/site-packages/sqlalchemy/engine/create.py", line 574, in connect
    return dialect.connect(*cargs, **cparams)
  File "/home/airflow/.local/lib/python3.7/site-packages/sqlalchemy/engine/default.py", line 598, in connect
    return self.dbapi.connect(*cargs, **cparams)
  File "/home/airflow/.local/lib/python3.7/site-packages/psycopg2/__init__.py", line 122, in connect
    conn = _connect(dsn, connection_factory=connection_factory, **kwasync)
psycopg2.OperationalError: could not translate host name "postgres" to address: Temporary failure in name resolution


The above exception was the direct cause of the following exception:

Traceback (most recent call last):
  File "/home/airflow/.local/lib/python3.7/site-packages/airflow/jobs/job.py", line 187, in heartbeat
    session.merge(self)
  File "/home/airflow/.local/lib/python3.7/site-packages/sqlalchemy/orm/session.py", line 3062, in merge
    _resolve_conflict_map=_resolve_conflict_map,
  File "/home/airflow/.local/lib/python3.7/site-packages/sqlalchemy/orm/session.py", line 3140, in _merge
    options=options,
  File "/home/airflow/.local/lib/python3.7/site-packages/sqlalchemy/orm/session.py", line 2861, in get
    execution_options=execution_options,
  File "/home/airflow/.local/lib/python3.7/site-packages/sqlalchemy/orm/session.py", line 2979, in _get_impl
    load_options=load_options,
  File "/home/airflow/.local/lib/python3.7/site-packages/sqlalchemy/orm/loading.py", line 534, in load_on_pk_identity
    bind_arguments=bind_arguments,
  File "/home/airflow/.local/lib/python3.7/site-packages/sqlalchemy/orm/session.py", line 1716, in execute
    conn = self._connection_for_bind(bind)
  File "/home/airflow/.local/lib/python3.7/site-packages/sqlalchemy/orm/session.py", line 1556, in _connection_for_bind
    engine, execution_options
  File "/home/airflow/.local/lib/python3.7/site-packages/sqlalchemy/orm/session.py", line 750, in _connection_for_bind
    conn = bind.connect()
  File "/home/airflow/.local/lib/python3.7/site-packages/sqlalchemy/engine/base.py", line 3320, in connect
    return self._connection_cls(self, close_with_result=close_with_result)
  File "/home/airflow/.local/lib/python3.7/site-packages/sqlalchemy/engine/base.py", line 96, in __init__
    else engine.raw_connection()
  File "/home/airflow/.local/lib/python3.7/site-packages/sqlalchemy/engine/base.py", line 3399, in raw_connection
    return self._wrap_pool_connect(self.pool.connect, _connection)
  File "/home/airflow/.local/lib/python3.7/site-packages/sqlalchemy/engine/base.py", line 3370, in _wrap_pool_connect
    e, dialect, self
  File "/home/airflow/.local/lib/python3.7/site-packages/sqlalchemy/engine/base.py", line 2204, in _handle_dbapi_exception_noconnection
    sqlalchemy_exception, with_traceback=exc_info[2], from_=e
  File "/home/airflow/.local/lib/python3.7/site-packages/sqlalchemy/util/compat.py", line 211, in raise_
    raise exception
  File "/home/airflow/.local/lib/python3.7/site-packages/sqlalchemy/engine/base.py", line 3366, in _wrap_pool_connect
    return fn()
  File "/home/airflow/.local/lib/python3.7/site-packages/sqlalchemy/pool/base.py", line 327, in connect
    return _ConnectionFairy._checkout(self)
  File "/home/airflow/.local/lib/python3.7/site-packages/sqlalchemy/pool/base.py", line 894, in _checkout
    fairy = _ConnectionRecord.checkout(pool)
  File "/home/airflow/.local/lib/python3.7/site-packages/sqlalchemy/pool/base.py", line 493, in checkout
    rec = pool._do_get()
  File "/home/airflow/.local/lib/python3.7/site-packages/sqlalchemy/pool/impl.py", line 256, in _do_get
    return self._create_connection()
  File "/home/airflow/.local/lib/python3.7/site-packages/sqlalchemy/pool/base.py", line 273, in _create_connection
    return _ConnectionRecord(self)
  File "/home/airflow/.local/lib/python3.7/site-packages/sqlalchemy/pool/base.py", line 388, in __init__
    self.__connect()
  File "/home/airflow/.local/lib/python3.7/site-packages/sqlalchemy/pool/base.py", line 691, in __connect
    pool.logger.debug("Error on connect(): %s", e)
  File "/home/airflow/.local/lib/python3.7/site-packages/sqlalchemy/util/langhelpers.py", line 72, in __exit__
    with_traceback=exc_tb,
  File "/home/airflow/.local/lib/python3.7/site-packages/sqlalchemy/util/compat.py", line 211, in raise_
    raise exception
  File "/home/airflow/.local/lib/python3.7/site-packages/sqlalchemy/pool/base.py", line 686, in __connect
    self.dbapi_connection = connection = pool._invoke_creator(self)
  File "/home/airflow/.local/lib/python3.7/site-packages/sqlalchemy/engine/create.py", line 574, in connect
    return dialect.connect(*cargs, **cparams)
  File "/home/airflow/.local/lib/python3.7/site-packages/sqlalchemy/engine/default.py", line 598, in connect
    return self.dbapi.connect(*cargs, **cparams)
  File "/home/airflow/.local/lib/python3.7/site-packages/psycopg2/__init__.py", line 122, in connect
    conn = _connect(dsn, connection_factory=connection_factory, **kwasync)
sqlalchemy.exc.OperationalError: (psycopg2.OperationalError) could not translate host name "postgres" to address: Temporary failure in name resolution

(Background on this error at: https://sqlalche.me/e/14/e3q8)
[2023-06-27T08:43:35.974+0000] {subprocess.py:93} INFO - [0m08:43:35  [[33mWARNING[0m]: Configuration paths exist in your dbt_project.yml file which do not apply to any resources.
[2023-06-27T08:43:35.978+0000] {subprocess.py:93} INFO - There are 2 unused configuration paths:
[2023-06-27T08:43:35.980+0000] {subprocess.py:93} INFO - - models.badge_5.time_of_day
[2023-06-27T08:43:35.983+0000] {subprocess.py:93} INFO - - models.badge_5.create_stage
[2023-06-27T08:43:36.149+0000] {subprocess.py:93} INFO - [0m08:43:36  Found 2 models, 0 tests, 0 snapshots, 0 analyses, 455 macros, 0 operations, 1 seed file, 0 sources, 0 exposures, 0 metrics, 0 groups
[2023-06-27T08:43:36.158+0000] {subprocess.py:93} INFO - [0m08:43:36
[2023-06-27T08:43:37.861+0000] {subprocess.py:93} INFO - [0m08:43:37  Concurrency: 200 threads (target='dev')
[2023-06-27T08:43:37.868+0000] {subprocess.py:93} INFO - [0m08:43:37
[2023-06-27T08:43:38.198+0000] {subprocess.py:93} INFO - [0m08:43:38  1 of 1 START sql view model ***.select ..................................... [RUN]
[2023-06-27T08:43:38.968+0000] {subprocess.py:93} INFO - [0m08:43:38  1 of 1 ERROR creating sql view model ***.select ............................ [[31mERROR[0m in 0.74s]
[2023-06-27T08:43:39.096+0000] {subprocess.py:93} INFO - [0m08:43:39
[2023-06-27T08:43:39.099+0000] {subprocess.py:93} INFO - [0m08:43:39  Finished running 1 view model in 0 hours 0 minutes and 2.93 seconds (2.93s).
[2023-06-27T08:43:39.270+0000] {subprocess.py:93} INFO - [0m08:43:39
[2023-06-27T08:43:39.276+0000] {subprocess.py:93} INFO - [0m08:43:39  [31mCompleted with 1 error and 0 warnings:[0m
[2023-06-27T08:43:39.279+0000] {subprocess.py:93} INFO - [0m08:43:39
[2023-06-27T08:43:39.284+0000] {subprocess.py:93} INFO - [0m08:43:39  [33mDatabase Error in model select (models/select/select.sql)[0m
[2023-06-27T08:43:39.288+0000] {subprocess.py:93} INFO - [0m08:43:39    001003 (42000): SQL compilation error:
[2023-06-27T08:43:39.293+0000] {subprocess.py:93} INFO - [0m08:43:39    syntax error line 1 at position 43 unexpected '.'.
[2023-06-27T08:43:39.316+0000] {subprocess.py:93} INFO - [0m08:43:39    compiled Code at target/run/badge_5/models/select/select.sql
[2023-06-27T08:43:39.317+0000] {subprocess.py:93} INFO - [0m08:43:39
[2023-06-27T08:43:39.333+0000] {subprocess.py:93} INFO - [0m08:43:39  Done. PASS=0 WARN=0 ERROR=1 SKIP=0 TOTAL=1
[2023-06-27T08:43:40.347+0000] {subprocess.py:97} INFO - Command exited with return code 1
[2023-06-27T08:43:40.364+0000] {taskinstance.py:1824} ERROR - Task failed with exception
Traceback (most recent call last):
  File "/home/airflow/.local/lib/python3.7/site-packages/airflow/operators/bash.py", line 211, in execute
    f"Bash command failed. The command returned a non-zero exit code {result.exit_code}."
airflow.exceptions.AirflowException: Bash command failed. The command returned a non-zero exit code 1.
[2023-06-27T08:43:40.371+0000] {taskinstance.py:1350} INFO - Marking task as FAILED. dag_id=2_Test_Badge_5_Loop, task_id=create_select, execution_date=20230627T022000, start_date=20230627T084217, end_date=20230627T084340
[2023-06-27T08:43:40.405+0000] {standard_task_runner.py:109} ERROR - Failed to execute job 168 for task create_select (Bash command failed. The command returned a non-zero exit code 1.; 4485)
[2023-06-27T08:43:40.446+0000] {local_task_job_runner.py:225} INFO - Task exited with return code 1
[2023-06-27T08:43:40.468+0000] {taskinstance.py:2651} INFO - 0 downstream tasks scheduled from follow-on schedule check
