[2023-06-27T11:31:51.011+0000] {logging_mixin.py:149} INFO - Changing /opt/***/logs/dag_id=2_Test_Badge_5_Setup/run_id=manual__2023-06-27T11:31:48.405473+00:00/task_id=load_seed_todl_once permission to 509
[2023-06-27T11:31:51.012+0000] {logging_mixin.py:149} INFO - Failed to change /opt/***/logs/dag_id=2_Test_Badge_5_Setup/run_id=manual__2023-06-27T11:31:48.405473+00:00/task_id=load_seed_todl_once permission to 509: [Errno 1] Operation not permitted: '/opt/***/logs/dag_id=2_Test_Badge_5_Setup/run_id=manual__2023-06-27T11:31:48.405473+00:00/task_id=load_seed_todl_once'
[2023-06-27T11:31:51.045+0000] {logging_mixin.py:149} INFO - Changing /opt/***/logs/dag_id=2_Test_Badge_5_Setup/run_id=manual__2023-06-27T11:31:48.405473+00:00/task_id=load_seed_todl_once permission to 509
[2023-06-27T11:31:51.047+0000] {logging_mixin.py:149} INFO - Failed to change /opt/***/logs/dag_id=2_Test_Badge_5_Setup/run_id=manual__2023-06-27T11:31:48.405473+00:00/task_id=load_seed_todl_once permission to 509: [Errno 1] Operation not permitted: '/opt/***/logs/dag_id=2_Test_Badge_5_Setup/run_id=manual__2023-06-27T11:31:48.405473+00:00/task_id=load_seed_todl_once'
[2023-06-27T11:31:51.088+0000] {taskinstance.py:1103} INFO - Dependencies all met for dep_context=non-requeueable deps ti=<TaskInstance: 2_Test_Badge_5_Setup.load_seed_todl_once manual__2023-06-27T11:31:48.405473+00:00 [queued]>
[2023-06-27T11:31:51.099+0000] {taskinstance.py:1103} INFO - Dependencies all met for dep_context=requeueable deps ti=<TaskInstance: 2_Test_Badge_5_Setup.load_seed_todl_once manual__2023-06-27T11:31:48.405473+00:00 [queued]>
[2023-06-27T11:31:51.100+0000] {taskinstance.py:1308} INFO - Starting attempt 1 of 1
[2023-06-27T11:31:51.122+0000] {taskinstance.py:1327} INFO - Executing <Task(BashOperator): load_seed_todl_once> on 2023-06-27 11:31:48.405473+00:00
[2023-06-27T11:31:51.131+0000] {standard_task_runner.py:57} INFO - Started process 106 to run task
[2023-06-27T11:31:51.136+0000] {standard_task_runner.py:84} INFO - Running: ['***', 'tasks', 'run', '2_Test_Badge_5_Setup', 'load_seed_todl_once', 'manual__2023-06-27T11:31:48.405473+00:00', '--job-id', '263', '--raw', '--subdir', 'DAGS_FOLDER/test.py', '--cfg-path', '/tmp/tmppouj0mma']
[2023-06-27T11:31:51.139+0000] {standard_task_runner.py:85} INFO - Job 263: Subtask load_seed_todl_once
[2023-06-27T11:31:51.204+0000] {logging_mixin.py:149} INFO - Changing /opt/***/logs/dag_id=2_Test_Badge_5_Setup/run_id=manual__2023-06-27T11:31:48.405473+00:00/task_id=load_seed_todl_once permission to 509
[2023-06-27T11:31:51.205+0000] {logging_mixin.py:149} INFO - Failed to change /opt/***/logs/dag_id=2_Test_Badge_5_Setup/run_id=manual__2023-06-27T11:31:48.405473+00:00/task_id=load_seed_todl_once permission to 509: [Errno 1] Operation not permitted: '/opt/***/logs/dag_id=2_Test_Badge_5_Setup/run_id=manual__2023-06-27T11:31:48.405473+00:00/task_id=load_seed_todl_once'
[2023-06-27T11:31:51.209+0000] {task_command.py:410} INFO - Running <TaskInstance: 2_Test_Badge_5_Setup.load_seed_todl_once manual__2023-06-27T11:31:48.405473+00:00 [running]> on host 117903831da4
[2023-06-27T11:31:51.376+0000] {taskinstance.py:1547} INFO - Exporting env vars: AIRFLOW_CTX_DAG_OWNER='***' AIRFLOW_CTX_DAG_ID='2_Test_Badge_5_Setup' AIRFLOW_CTX_TASK_ID='load_seed_todl_once' AIRFLOW_CTX_EXECUTION_DATE='2023-06-27T11:31:48.405473+00:00' AIRFLOW_CTX_TRY_NUMBER='1' AIRFLOW_CTX_DAG_RUN_ID='manual__2023-06-27T11:31:48.405473+00:00'
[2023-06-27T11:31:51.379+0000] {subprocess.py:63} INFO - Tmp dir root location: 
 /tmp
[2023-06-27T11:31:51.380+0000] {subprocess.py:75} INFO - Running command: ['/bin/bash', '-c', 'cd /dbt && dbt seed --profiles-dir .']
[2023-06-27T11:31:51.393+0000] {subprocess.py:86} INFO - Output:
[2023-06-27T11:31:55.401+0000] {subprocess.py:93} INFO - [0m11:31:55  Running with dbt=1.5.1
[2023-06-27T11:32:01.696+0000] {subprocess.py:93} INFO - [0m11:32:01  Found 2 models, 0 tests, 0 snapshots, 0 analyses, 456 macros, 0 operations, 1 seed file, 0 sources, 0 exposures, 0 metrics, 0 groups
[2023-06-27T11:32:01.700+0000] {subprocess.py:93} INFO - [0m11:32:01
[2023-06-27T11:32:02.872+0000] {subprocess.py:93} INFO - [0m11:32:02  Concurrency: 200 threads (target='dev')
[2023-06-27T11:32:02.874+0000] {subprocess.py:93} INFO - [0m11:32:02
[2023-06-27T11:32:02.931+0000] {subprocess.py:93} INFO - [0m11:32:02  1 of 1 START seed file ***.time_of_day_lu .................................. [RUN]
[2023-06-27T11:32:02.974+0000] {subprocess.py:93} INFO - [0m11:32:02  [31mUnhandled error while executing [0m
[2023-06-27T11:32:02.974+0000] {subprocess.py:93} INFO - [Errno 2] No such file or directory: '/mnt/d/IPPON/Airflow/Project/Badge_Airflow/badge_5/seeds/time_of_day_lu.csv'
[2023-06-27T11:32:02.979+0000] {subprocess.py:93} INFO - [0m11:32:02  1 of 1 ERROR loading seed file ***.time_of_day_lu .......................... [[31mERROR[0m in 0.05s]
[2023-06-27T11:32:03.050+0000] {subprocess.py:93} INFO - [0m11:32:03
[2023-06-27T11:32:03.051+0000] {subprocess.py:93} INFO - [0m11:32:03  Finished running 1 seed in 0 hours 0 minutes and 1.35 seconds (1.35s).
[2023-06-27T11:32:03.086+0000] {subprocess.py:93} INFO - [0m11:32:03
[2023-06-27T11:32:03.087+0000] {subprocess.py:93} INFO - [0m11:32:03  [31mCompleted with 1 error and 0 warnings:[0m
[2023-06-27T11:32:03.089+0000] {subprocess.py:93} INFO - [0m11:32:03
[2023-06-27T11:32:03.090+0000] {subprocess.py:93} INFO - [0m11:32:03  [33m[Errno 2] No such file or directory: '/mnt/d/IPPON/Airflow/Project/Badge_Airflow/badge_5/seeds/time_of_day_lu.csv'[0m
[2023-06-27T11:32:03.091+0000] {subprocess.py:93} INFO - [0m11:32:03
[2023-06-27T11:32:03.093+0000] {subprocess.py:93} INFO - [0m11:32:03  Done. PASS=0 WARN=0 ERROR=1 SKIP=0 TOTAL=1
[2023-06-27T11:32:03.740+0000] {subprocess.py:97} INFO - Command exited with return code 1
[2023-06-27T11:32:03.753+0000] {taskinstance.py:1824} ERROR - Task failed with exception
Traceback (most recent call last):
  File "/home/airflow/.local/lib/python3.7/site-packages/airflow/operators/bash.py", line 211, in execute
    f"Bash command failed. The command returned a non-zero exit code {result.exit_code}."
airflow.exceptions.AirflowException: Bash command failed. The command returned a non-zero exit code 1.
[2023-06-27T11:32:03.757+0000] {taskinstance.py:1350} INFO - Marking task as FAILED. dag_id=2_Test_Badge_5_Setup, task_id=load_seed_todl_once, execution_date=20230627T113148, start_date=20230627T113151, end_date=20230627T113203
[2023-06-27T11:32:03.772+0000] {standard_task_runner.py:109} ERROR - Failed to execute job 263 for task load_seed_todl_once (Bash command failed. The command returned a non-zero exit code 1.; 106)
[2023-06-27T11:32:03.851+0000] {local_task_job_runner.py:225} INFO - Task exited with return code 1
[2023-06-27T11:32:03.881+0000] {taskinstance.py:2651} INFO - 0 downstream tasks scheduled from follow-on schedule check
