[2023-06-27T08:42:13.428+0000] {logging_mixin.py:149} INFO - Changing /opt/***/logs/dag_id=2_Test_Badge_5_Loop/run_id=scheduled__2023-06-27T01:45:00+00:00/task_id=create_select permission to 509
[2023-06-27T08:42:13.440+0000] {logging_mixin.py:149} INFO - Failed to change /opt/***/logs/dag_id=2_Test_Badge_5_Loop/run_id=scheduled__2023-06-27T01:45:00+00:00/task_id=create_select permission to 509: [Errno 1] Operation not permitted: '/opt/***/logs/dag_id=2_Test_Badge_5_Loop/run_id=scheduled__2023-06-27T01:45:00+00:00/task_id=create_select'
[2023-06-27T08:42:13.622+0000] {logging_mixin.py:149} INFO - Changing /opt/***/logs/dag_id=2_Test_Badge_5_Loop/run_id=scheduled__2023-06-27T01:45:00+00:00/task_id=create_select permission to 509
[2023-06-27T08:42:13.624+0000] {logging_mixin.py:149} INFO - Failed to change /opt/***/logs/dag_id=2_Test_Badge_5_Loop/run_id=scheduled__2023-06-27T01:45:00+00:00/task_id=create_select permission to 509: [Errno 1] Operation not permitted: '/opt/***/logs/dag_id=2_Test_Badge_5_Loop/run_id=scheduled__2023-06-27T01:45:00+00:00/task_id=create_select'
[2023-06-27T08:42:16.790+0000] {taskinstance.py:1103} INFO - Dependencies all met for dep_context=non-requeueable deps ti=<TaskInstance: 2_Test_Badge_5_Loop.create_select scheduled__2023-06-27T01:45:00+00:00 [queued]>
[2023-06-27T08:42:16.811+0000] {taskinstance.py:1103} INFO - Dependencies all met for dep_context=requeueable deps ti=<TaskInstance: 2_Test_Badge_5_Loop.create_select scheduled__2023-06-27T01:45:00+00:00 [queued]>
[2023-06-27T08:42:16.812+0000] {taskinstance.py:1308} INFO - Starting attempt 1 of 1
[2023-06-27T08:42:16.850+0000] {taskinstance.py:1327} INFO - Executing <Task(BashOperator): create_select> on 2023-06-27 01:45:00+00:00
[2023-06-27T08:42:16.862+0000] {standard_task_runner.py:57} INFO - Started process 4479 to run task
[2023-06-27T08:42:16.871+0000] {standard_task_runner.py:84} INFO - Running: ['***', 'tasks', 'run', '2_Test_Badge_5_Loop', 'create_select', 'scheduled__2023-06-27T01:45:00+00:00', '--job-id', '165', '--raw', '--subdir', 'DAGS_FOLDER/test.py', '--cfg-path', '/tmp/tmpl7x07hi4']
[2023-06-27T08:42:16.875+0000] {standard_task_runner.py:85} INFO - Job 165: Subtask create_select
[2023-06-27T08:42:17.005+0000] {logging_mixin.py:149} INFO - Changing /opt/***/logs/dag_id=2_Test_Badge_5_Loop/run_id=scheduled__2023-06-27T01:45:00+00:00/task_id=create_select permission to 509
[2023-06-27T08:42:17.006+0000] {logging_mixin.py:149} INFO - Failed to change /opt/***/logs/dag_id=2_Test_Badge_5_Loop/run_id=scheduled__2023-06-27T01:45:00+00:00/task_id=create_select permission to 509: [Errno 1] Operation not permitted: '/opt/***/logs/dag_id=2_Test_Badge_5_Loop/run_id=scheduled__2023-06-27T01:45:00+00:00/task_id=create_select'
[2023-06-27T08:42:17.014+0000] {task_command.py:410} INFO - Running <TaskInstance: 2_Test_Badge_5_Loop.create_select scheduled__2023-06-27T01:45:00+00:00 [running]> on host 4d37da440d5c
[2023-06-27T08:42:17.355+0000] {taskinstance.py:1547} INFO - Exporting env vars: AIRFLOW_CTX_DAG_OWNER='***' AIRFLOW_CTX_DAG_ID='2_Test_Badge_5_Loop' AIRFLOW_CTX_TASK_ID='create_select' AIRFLOW_CTX_EXECUTION_DATE='2023-06-27T01:45:00+00:00' AIRFLOW_CTX_TRY_NUMBER='1' AIRFLOW_CTX_DAG_RUN_ID='scheduled__2023-06-27T01:45:00+00:00'
[2023-06-27T08:42:17.360+0000] {subprocess.py:63} INFO - Tmp dir root location: 
 /tmp
[2023-06-27T08:42:17.363+0000] {subprocess.py:75} INFO - Running command: ['/bin/bash', '-c', 'cd /dbt && dbt run --model select']
[2023-06-27T08:42:17.394+0000] {subprocess.py:86} INFO - Output:
[2023-06-27T08:42:43.216+0000] {job.py:216} ERROR - Job heartbeat got an exception
Traceback (most recent call last):
  File "/home/airflow/.local/lib/python3.7/site-packages/sqlalchemy/engine/base.py", line 3366, in _wrap_pool_connect
    return fn()
  File "/home/airflow/.local/lib/python3.7/site-packages/sqlalchemy/pool/base.py", line 327, in connect
    return _ConnectionFairy._checkout(self)
  File "/home/airflow/.local/lib/python3.7/site-packages/sqlalchemy/pool/base.py", line 894, in _checkout
    fairy = _ConnectionRecord.checkout(pool)
  File "/home/airflow/.local/lib/python3.7/site-packages/sqlalchemy/pool/base.py", line 493, in checkout
    rec = pool._do_get()
  File "/home/airflow/.local/lib/python3.7/site-packages/sqlalchemy/pool/impl.py", line 256, in _do_get
    return self._create_connection()
  File "/home/airflow/.local/lib/python3.7/site-packages/sqlalchemy/pool/base.py", line 273, in _create_connection
    return _ConnectionRecord(self)
  File "/home/airflow/.local/lib/python3.7/site-packages/sqlalchemy/pool/base.py", line 388, in __init__
    self.__connect()
  File "/home/airflow/.local/lib/python3.7/site-packages/sqlalchemy/pool/base.py", line 691, in __connect
    pool.logger.debug("Error on connect(): %s", e)
  File "/home/airflow/.local/lib/python3.7/site-packages/sqlalchemy/util/langhelpers.py", line 72, in __exit__
    with_traceback=exc_tb,
  File "/home/airflow/.local/lib/python3.7/site-packages/sqlalchemy/util/compat.py", line 211, in raise_
    raise exception
  File "/home/airflow/.local/lib/python3.7/site-packages/sqlalchemy/pool/base.py", line 686, in __connect
    self.dbapi_connection = connection = pool._invoke_creator(self)
  File "/home/airflow/.local/lib/python3.7/site-packages/sqlalchemy/engine/create.py", line 574, in connect
    return dialect.connect(*cargs, **cparams)
  File "/home/airflow/.local/lib/python3.7/site-packages/sqlalchemy/engine/default.py", line 598, in connect
    return self.dbapi.connect(*cargs, **cparams)
  File "/home/airflow/.local/lib/python3.7/site-packages/psycopg2/__init__.py", line 122, in connect
    conn = _connect(dsn, connection_factory=connection_factory, **kwasync)
psycopg2.OperationalError: could not translate host name "postgres" to address: Temporary failure in name resolution


The above exception was the direct cause of the following exception:

Traceback (most recent call last):
  File "/home/airflow/.local/lib/python3.7/site-packages/airflow/jobs/job.py", line 187, in heartbeat
    session.merge(self)
  File "/home/airflow/.local/lib/python3.7/site-packages/sqlalchemy/orm/session.py", line 3062, in merge
    _resolve_conflict_map=_resolve_conflict_map,
  File "/home/airflow/.local/lib/python3.7/site-packages/sqlalchemy/orm/session.py", line 3140, in _merge
    options=options,
  File "/home/airflow/.local/lib/python3.7/site-packages/sqlalchemy/orm/session.py", line 2861, in get
    execution_options=execution_options,
  File "/home/airflow/.local/lib/python3.7/site-packages/sqlalchemy/orm/session.py", line 2979, in _get_impl
    load_options=load_options,
  File "/home/airflow/.local/lib/python3.7/site-packages/sqlalchemy/orm/loading.py", line 534, in load_on_pk_identity
    bind_arguments=bind_arguments,
  File "/home/airflow/.local/lib/python3.7/site-packages/sqlalchemy/orm/session.py", line 1716, in execute
    conn = self._connection_for_bind(bind)
  File "/home/airflow/.local/lib/python3.7/site-packages/sqlalchemy/orm/session.py", line 1556, in _connection_for_bind
    engine, execution_options
  File "/home/airflow/.local/lib/python3.7/site-packages/sqlalchemy/orm/session.py", line 750, in _connection_for_bind
    conn = bind.connect()
  File "/home/airflow/.local/lib/python3.7/site-packages/sqlalchemy/engine/base.py", line 3320, in connect
    return self._connection_cls(self, close_with_result=close_with_result)
  File "/home/airflow/.local/lib/python3.7/site-packages/sqlalchemy/engine/base.py", line 96, in __init__
    else engine.raw_connection()
  File "/home/airflow/.local/lib/python3.7/site-packages/sqlalchemy/engine/base.py", line 3399, in raw_connection
    return self._wrap_pool_connect(self.pool.connect, _connection)
  File "/home/airflow/.local/lib/python3.7/site-packages/sqlalchemy/engine/base.py", line 3370, in _wrap_pool_connect
    e, dialect, self
  File "/home/airflow/.local/lib/python3.7/site-packages/sqlalchemy/engine/base.py", line 2204, in _handle_dbapi_exception_noconnection
    sqlalchemy_exception, with_traceback=exc_info[2], from_=e
  File "/home/airflow/.local/lib/python3.7/site-packages/sqlalchemy/util/compat.py", line 211, in raise_
    raise exception
  File "/home/airflow/.local/lib/python3.7/site-packages/sqlalchemy/engine/base.py", line 3366, in _wrap_pool_connect
    return fn()
  File "/home/airflow/.local/lib/python3.7/site-packages/sqlalchemy/pool/base.py", line 327, in connect
    return _ConnectionFairy._checkout(self)
  File "/home/airflow/.local/lib/python3.7/site-packages/sqlalchemy/pool/base.py", line 894, in _checkout
    fairy = _ConnectionRecord.checkout(pool)
  File "/home/airflow/.local/lib/python3.7/site-packages/sqlalchemy/pool/base.py", line 493, in checkout
    rec = pool._do_get()
  File "/home/airflow/.local/lib/python3.7/site-packages/sqlalchemy/pool/impl.py", line 256, in _do_get
    return self._create_connection()
  File "/home/airflow/.local/lib/python3.7/site-packages/sqlalchemy/pool/base.py", line 273, in _create_connection
    return _ConnectionRecord(self)
  File "/home/airflow/.local/lib/python3.7/site-packages/sqlalchemy/pool/base.py", line 388, in __init__
    self.__connect()
  File "/home/airflow/.local/lib/python3.7/site-packages/sqlalchemy/pool/base.py", line 691, in __connect
    pool.logger.debug("Error on connect(): %s", e)
  File "/home/airflow/.local/lib/python3.7/site-packages/sqlalchemy/util/langhelpers.py", line 72, in __exit__
    with_traceback=exc_tb,
  File "/home/airflow/.local/lib/python3.7/site-packages/sqlalchemy/util/compat.py", line 211, in raise_
    raise exception
  File "/home/airflow/.local/lib/python3.7/site-packages/sqlalchemy/pool/base.py", line 686, in __connect
    self.dbapi_connection = connection = pool._invoke_creator(self)
  File "/home/airflow/.local/lib/python3.7/site-packages/sqlalchemy/engine/create.py", line 574, in connect
    return dialect.connect(*cargs, **cparams)
  File "/home/airflow/.local/lib/python3.7/site-packages/sqlalchemy/engine/default.py", line 598, in connect
    return self.dbapi.connect(*cargs, **cparams)
  File "/home/airflow/.local/lib/python3.7/site-packages/psycopg2/__init__.py", line 122, in connect
    conn = _connect(dsn, connection_factory=connection_factory, **kwasync)
sqlalchemy.exc.OperationalError: (psycopg2.OperationalError) could not translate host name "postgres" to address: Temporary failure in name resolution

(Background on this error at: https://sqlalche.me/e/14/e3q8)
[2023-06-27T08:43:04.003+0000] {subprocess.py:93} INFO - [0m08:43:04  Running with dbt=1.5.1
[2023-06-27T08:43:37.621+0000] {subprocess.py:93} INFO - [0m08:43:37  [[33mWARNING[0m]: Configuration paths exist in your dbt_project.yml file which do not apply to any resources.
[2023-06-27T08:43:37.624+0000] {subprocess.py:93} INFO - There are 2 unused configuration paths:
[2023-06-27T08:43:37.625+0000] {subprocess.py:93} INFO - - models.badge_5.time_of_day
[2023-06-27T08:43:37.627+0000] {subprocess.py:93} INFO - - models.badge_5.create_stage
[2023-06-27T08:43:37.736+0000] {subprocess.py:93} INFO - [0m08:43:37  Found 2 models, 0 tests, 0 snapshots, 0 analyses, 455 macros, 0 operations, 1 seed file, 0 sources, 0 exposures, 0 metrics, 0 groups
[2023-06-27T08:43:37.747+0000] {subprocess.py:93} INFO - [0m08:43:37
[2023-06-27T08:43:39.675+0000] {subprocess.py:93} INFO - [0m08:43:39  Concurrency: 200 threads (target='dev')
[2023-06-27T08:43:39.677+0000] {subprocess.py:93} INFO - [0m08:43:39
[2023-06-27T08:43:39.774+0000] {subprocess.py:93} INFO - [0m08:43:39  1 of 1 START sql view model ***.select ..................................... [RUN]
[2023-06-27T08:43:40.421+0000] {subprocess.py:93} INFO - [0m08:43:40  1 of 1 ERROR creating sql view model ***.select ............................ [[31mERROR[0m in 0.64s]
[2023-06-27T08:43:40.506+0000] {subprocess.py:93} INFO - [0m08:43:40
[2023-06-27T08:43:40.508+0000] {subprocess.py:93} INFO - [0m08:43:40  Finished running 1 view model in 0 hours 0 minutes and 2.76 seconds (2.76s).
[2023-06-27T08:43:40.550+0000] {subprocess.py:93} INFO - [0m08:43:40
[2023-06-27T08:43:40.551+0000] {subprocess.py:93} INFO - [0m08:43:40  [31mCompleted with 1 error and 0 warnings:[0m
[2023-06-27T08:43:40.553+0000] {subprocess.py:93} INFO - [0m08:43:40
[2023-06-27T08:43:40.555+0000] {subprocess.py:93} INFO - [0m08:43:40  [33mDatabase Error in model select (models/select/select.sql)[0m
[2023-06-27T08:43:40.558+0000] {subprocess.py:93} INFO - [0m08:43:40    001003 (42000): SQL compilation error:
[2023-06-27T08:43:40.560+0000] {subprocess.py:93} INFO - [0m08:43:40    syntax error line 1 at position 43 unexpected '.'.
[2023-06-27T08:43:40.562+0000] {subprocess.py:93} INFO - [0m08:43:40    compiled Code at target/run/badge_5/models/select/select.sql
[2023-06-27T08:43:40.563+0000] {subprocess.py:93} INFO - [0m08:43:40
[2023-06-27T08:43:40.564+0000] {subprocess.py:93} INFO - [0m08:43:40  Done. PASS=0 WARN=0 ERROR=1 SKIP=0 TOTAL=1
[2023-06-27T08:43:41.588+0000] {subprocess.py:97} INFO - Command exited with return code 1
[2023-06-27T08:43:41.607+0000] {taskinstance.py:1824} ERROR - Task failed with exception
Traceback (most recent call last):
  File "/home/airflow/.local/lib/python3.7/site-packages/airflow/operators/bash.py", line 211, in execute
    f"Bash command failed. The command returned a non-zero exit code {result.exit_code}."
airflow.exceptions.AirflowException: Bash command failed. The command returned a non-zero exit code 1.
[2023-06-27T08:43:41.616+0000] {taskinstance.py:1350} INFO - Marking task as FAILED. dag_id=2_Test_Badge_5_Loop, task_id=create_select, execution_date=20230627T014500, start_date=20230627T084216, end_date=20230627T084341
[2023-06-27T08:43:41.638+0000] {standard_task_runner.py:109} ERROR - Failed to execute job 165 for task create_select (Bash command failed. The command returned a non-zero exit code 1.; 4479)
[2023-06-27T08:43:41.670+0000] {local_task_job_runner.py:225} INFO - Task exited with return code 1
[2023-06-27T08:43:41.693+0000] {taskinstance.py:2651} INFO - 0 downstream tasks scheduled from follow-on schedule check
