[2023-06-27T09:22:45.005+0000] {logging_mixin.py:149} INFO - Changing /opt/***/logs/dag_id=2_Test_Badge_5_Loop/run_id=manual__2023-06-27T09:22:43.973393+00:00/task_id=create_select permission to 509
[2023-06-27T09:22:45.006+0000] {logging_mixin.py:149} INFO - Failed to change /opt/***/logs/dag_id=2_Test_Badge_5_Loop/run_id=manual__2023-06-27T09:22:43.973393+00:00/task_id=create_select permission to 509: [Errno 1] Operation not permitted: '/opt/***/logs/dag_id=2_Test_Badge_5_Loop/run_id=manual__2023-06-27T09:22:43.973393+00:00/task_id=create_select'
[2023-06-27T09:22:45.035+0000] {logging_mixin.py:149} INFO - Changing /opt/***/logs/dag_id=2_Test_Badge_5_Loop/run_id=manual__2023-06-27T09:22:43.973393+00:00/task_id=create_select permission to 509
[2023-06-27T09:22:45.036+0000] {logging_mixin.py:149} INFO - Failed to change /opt/***/logs/dag_id=2_Test_Badge_5_Loop/run_id=manual__2023-06-27T09:22:43.973393+00:00/task_id=create_select permission to 509: [Errno 1] Operation not permitted: '/opt/***/logs/dag_id=2_Test_Badge_5_Loop/run_id=manual__2023-06-27T09:22:43.973393+00:00/task_id=create_select'
[2023-06-27T09:22:45.186+0000] {taskinstance.py:1103} INFO - Dependencies all met for dep_context=non-requeueable deps ti=<TaskInstance: 2_Test_Badge_5_Loop.create_select manual__2023-06-27T09:22:43.973393+00:00 [queued]>
[2023-06-27T09:22:45.196+0000] {taskinstance.py:1103} INFO - Dependencies all met for dep_context=requeueable deps ti=<TaskInstance: 2_Test_Badge_5_Loop.create_select manual__2023-06-27T09:22:43.973393+00:00 [queued]>
[2023-06-27T09:22:45.197+0000] {taskinstance.py:1308} INFO - Starting attempt 1 of 1
[2023-06-27T09:22:45.213+0000] {taskinstance.py:1327} INFO - Executing <Task(BashOperator): create_select> on 2023-06-27 09:22:43.973393+00:00
[2023-06-27T09:22:45.219+0000] {standard_task_runner.py:57} INFO - Started process 13706 to run task
[2023-06-27T09:22:45.222+0000] {standard_task_runner.py:84} INFO - Running: ['***', 'tasks', 'run', '2_Test_Badge_5_Loop', 'create_select', 'manual__2023-06-27T09:22:43.973393+00:00', '--job-id', '208', '--raw', '--subdir', 'DAGS_FOLDER/test.py', '--cfg-path', '/tmp/tmp5wenhmkx']
[2023-06-27T09:22:45.225+0000] {standard_task_runner.py:85} INFO - Job 208: Subtask create_select
[2023-06-27T09:22:45.271+0000] {logging_mixin.py:149} INFO - Changing /opt/***/logs/dag_id=2_Test_Badge_5_Loop/run_id=manual__2023-06-27T09:22:43.973393+00:00/task_id=create_select permission to 509
[2023-06-27T09:22:45.272+0000] {logging_mixin.py:149} INFO - Failed to change /opt/***/logs/dag_id=2_Test_Badge_5_Loop/run_id=manual__2023-06-27T09:22:43.973393+00:00/task_id=create_select permission to 509: [Errno 1] Operation not permitted: '/opt/***/logs/dag_id=2_Test_Badge_5_Loop/run_id=manual__2023-06-27T09:22:43.973393+00:00/task_id=create_select'
[2023-06-27T09:22:45.275+0000] {task_command.py:410} INFO - Running <TaskInstance: 2_Test_Badge_5_Loop.create_select manual__2023-06-27T09:22:43.973393+00:00 [running]> on host 4d37da440d5c
[2023-06-27T09:22:45.387+0000] {taskinstance.py:1547} INFO - Exporting env vars: AIRFLOW_CTX_DAG_OWNER='***' AIRFLOW_CTX_DAG_ID='2_Test_Badge_5_Loop' AIRFLOW_CTX_TASK_ID='create_select' AIRFLOW_CTX_EXECUTION_DATE='2023-06-27T09:22:43.973393+00:00' AIRFLOW_CTX_TRY_NUMBER='1' AIRFLOW_CTX_DAG_RUN_ID='manual__2023-06-27T09:22:43.973393+00:00'
[2023-06-27T09:22:45.389+0000] {subprocess.py:63} INFO - Tmp dir root location: 
 /tmp
[2023-06-27T09:22:45.389+0000] {subprocess.py:75} INFO - Running command: ['/bin/bash', '-c', 'cd /dbt && dbt run --model select']
[2023-06-27T09:22:45.400+0000] {subprocess.py:86} INFO - Output:
[2023-06-27T09:22:48.120+0000] {subprocess.py:93} INFO - [0m09:22:48  Running with dbt=1.5.1
[2023-06-27T09:22:55.559+0000] {subprocess.py:93} INFO - [0m09:22:55  [[33mWARNING[0m]: Configuration paths exist in your dbt_project.yml file which do not apply to any resources.
[2023-06-27T09:22:55.560+0000] {subprocess.py:93} INFO - There are 2 unused configuration paths:
[2023-06-27T09:22:55.561+0000] {subprocess.py:93} INFO - - models.badge_5.time_of_day
[2023-06-27T09:22:55.561+0000] {subprocess.py:93} INFO - - models.badge_5.create_stage
[2023-06-27T09:22:55.600+0000] {subprocess.py:93} INFO - [0m09:22:55  Found 2 models, 0 tests, 0 snapshots, 0 analyses, 455 macros, 0 operations, 1 seed file, 0 sources, 0 exposures, 0 metrics, 0 groups
[2023-06-27T09:22:55.603+0000] {subprocess.py:93} INFO - [0m09:22:55
[2023-06-27T09:22:56.843+0000] {subprocess.py:93} INFO - [0m09:22:56  Concurrency: 200 threads (target='dev')
[2023-06-27T09:22:56.844+0000] {subprocess.py:93} INFO - [0m09:22:56
[2023-06-27T09:22:56.889+0000] {subprocess.py:93} INFO - [0m09:22:56  1 of 1 START sql table model ***.select .................................... [RUN]
[2023-06-27T09:22:57.502+0000] {subprocess.py:93} INFO - [0m09:22:57  1 of 1 ERROR creating sql table model ***.select ........................... [[31mERROR[0m in 0.61s]
[2023-06-27T09:22:57.612+0000] {subprocess.py:93} INFO - [0m09:22:57
[2023-06-27T09:22:57.614+0000] {subprocess.py:93} INFO - [0m09:22:57  Finished running 1 table model in 0 hours 0 minutes and 2.01 seconds (2.01s).
[2023-06-27T09:22:57.650+0000] {subprocess.py:93} INFO - [0m09:22:57
[2023-06-27T09:22:57.652+0000] {subprocess.py:93} INFO - [0m09:22:57  [31mCompleted with 1 error and 0 warnings:[0m
[2023-06-27T09:22:57.654+0000] {subprocess.py:93} INFO - [0m09:22:57
[2023-06-27T09:22:57.655+0000] {subprocess.py:93} INFO - [0m09:22:57  [33mDatabase Error in model select (models/select/select.sql)[0m
[2023-06-27T09:22:57.657+0000] {subprocess.py:93} INFO - [0m09:22:57    001003 (42000): SQL compilation error:
[2023-06-27T09:22:57.658+0000] {subprocess.py:93} INFO - [0m09:22:57    syntax error line 1 at position 52 unexpected '.'.
[2023-06-27T09:22:57.659+0000] {subprocess.py:93} INFO - [0m09:22:57    compiled Code at target/run/badge_5/models/select/select.sql
[2023-06-27T09:22:57.660+0000] {subprocess.py:93} INFO - [0m09:22:57
[2023-06-27T09:22:57.662+0000] {subprocess.py:93} INFO - [0m09:22:57  Done. PASS=0 WARN=0 ERROR=1 SKIP=0 TOTAL=1
[2023-06-27T09:22:58.248+0000] {subprocess.py:97} INFO - Command exited with return code 1
[2023-06-27T09:22:58.259+0000] {taskinstance.py:1824} ERROR - Task failed with exception
Traceback (most recent call last):
  File "/home/airflow/.local/lib/python3.7/site-packages/airflow/operators/bash.py", line 211, in execute
    f"Bash command failed. The command returned a non-zero exit code {result.exit_code}."
airflow.exceptions.AirflowException: Bash command failed. The command returned a non-zero exit code 1.
[2023-06-27T09:22:58.263+0000] {taskinstance.py:1350} INFO - Marking task as FAILED. dag_id=2_Test_Badge_5_Loop, task_id=create_select, execution_date=20230627T092243, start_date=20230627T092245, end_date=20230627T092258
[2023-06-27T09:22:58.276+0000] {standard_task_runner.py:109} ERROR - Failed to execute job 208 for task create_select (Bash command failed. The command returned a non-zero exit code 1.; 13706)
[2023-06-27T09:22:58.387+0000] {local_task_job_runner.py:225} INFO - Task exited with return code 1
[2023-06-27T09:22:58.405+0000] {taskinstance.py:2651} INFO - 0 downstream tasks scheduled from follow-on schedule check
