[2023-06-23T15:10:37.673+0000] {logging_mixin.py:149} INFO - Changing /opt/***/logs/dag_id=2_Test_Badge_5/run_id=manual__2023-06-23T15:10:36.032032+00:00/task_id=test_create_stage permission to 509
[2023-06-23T15:10:37.674+0000] {logging_mixin.py:149} INFO - Failed to change /opt/***/logs/dag_id=2_Test_Badge_5/run_id=manual__2023-06-23T15:10:36.032032+00:00/task_id=test_create_stage permission to 509: [Errno 1] Operation not permitted: '/opt/***/logs/dag_id=2_Test_Badge_5/run_id=manual__2023-06-23T15:10:36.032032+00:00/task_id=test_create_stage'
[2023-06-23T15:10:37.699+0000] {logging_mixin.py:149} INFO - Changing /opt/***/logs/dag_id=2_Test_Badge_5/run_id=manual__2023-06-23T15:10:36.032032+00:00/task_id=test_create_stage permission to 509
[2023-06-23T15:10:37.700+0000] {logging_mixin.py:149} INFO - Failed to change /opt/***/logs/dag_id=2_Test_Badge_5/run_id=manual__2023-06-23T15:10:36.032032+00:00/task_id=test_create_stage permission to 509: [Errno 1] Operation not permitted: '/opt/***/logs/dag_id=2_Test_Badge_5/run_id=manual__2023-06-23T15:10:36.032032+00:00/task_id=test_create_stage'
[2023-06-23T15:10:37.855+0000] {taskinstance.py:1103} INFO - Dependencies all met for dep_context=non-requeueable deps ti=<TaskInstance: 2_Test_Badge_5.test_create_stage manual__2023-06-23T15:10:36.032032+00:00 [queued]>
[2023-06-23T15:10:37.864+0000] {taskinstance.py:1103} INFO - Dependencies all met for dep_context=requeueable deps ti=<TaskInstance: 2_Test_Badge_5.test_create_stage manual__2023-06-23T15:10:36.032032+00:00 [queued]>
[2023-06-23T15:10:37.865+0000] {taskinstance.py:1308} INFO - Starting attempt 1 of 1
[2023-06-23T15:10:37.881+0000] {taskinstance.py:1327} INFO - Executing <Task(BashOperator): test_create_stage> on 2023-06-23 15:10:36.032032+00:00
[2023-06-23T15:10:37.885+0000] {standard_task_runner.py:57} INFO - Started process 646 to run task
[2023-06-23T15:10:37.889+0000] {standard_task_runner.py:84} INFO - Running: ['***', 'tasks', 'run', '2_Test_Badge_5', 'test_create_stage', 'manual__2023-06-23T15:10:36.032032+00:00', '--job-id', '39', '--raw', '--subdir', 'DAGS_FOLDER/test.py', '--cfg-path', '/tmp/tmpjhj_0nds']
[2023-06-23T15:10:37.893+0000] {standard_task_runner.py:85} INFO - Job 39: Subtask test_create_stage
[2023-06-23T15:10:37.933+0000] {logging_mixin.py:149} INFO - Changing /opt/***/logs/dag_id=2_Test_Badge_5/run_id=manual__2023-06-23T15:10:36.032032+00:00/task_id=test_create_stage permission to 509
[2023-06-23T15:10:37.934+0000] {logging_mixin.py:149} INFO - Failed to change /opt/***/logs/dag_id=2_Test_Badge_5/run_id=manual__2023-06-23T15:10:36.032032+00:00/task_id=test_create_stage permission to 509: [Errno 1] Operation not permitted: '/opt/***/logs/dag_id=2_Test_Badge_5/run_id=manual__2023-06-23T15:10:36.032032+00:00/task_id=test_create_stage'
[2023-06-23T15:10:37.936+0000] {task_command.py:410} INFO - Running <TaskInstance: 2_Test_Badge_5.test_create_stage manual__2023-06-23T15:10:36.032032+00:00 [running]> on host 9b03f6d5dc98
[2023-06-23T15:10:38.044+0000] {taskinstance.py:1547} INFO - Exporting env vars: AIRFLOW_CTX_DAG_OWNER='***' AIRFLOW_CTX_DAG_ID='2_Test_Badge_5' AIRFLOW_CTX_TASK_ID='test_create_stage' AIRFLOW_CTX_EXECUTION_DATE='2023-06-23T15:10:36.032032+00:00' AIRFLOW_CTX_TRY_NUMBER='1' AIRFLOW_CTX_DAG_RUN_ID='manual__2023-06-23T15:10:36.032032+00:00'
[2023-06-23T15:10:38.046+0000] {subprocess.py:63} INFO - Tmp dir root location: 
 /tmp
[2023-06-23T15:10:38.047+0000] {subprocess.py:75} INFO - Running command: ['/bin/bash', '-c', 'cd /dbt && dbt run --model ed_pipeline_logs']
[2023-06-23T15:10:38.055+0000] {subprocess.py:86} INFO - Output:
[2023-06-23T15:10:40.527+0000] {subprocess.py:93} INFO - [0m15:10:40  Running with dbt=1.5.1
[2023-06-23T15:10:41.468+0000] {subprocess.py:93} INFO - [0m15:10:41  Unable to do partial parsing because profile has changed
[2023-06-23T15:10:47.752+0000] {subprocess.py:93} INFO - [0m15:10:47  Encountered an error:
[2023-06-23T15:10:47.752+0000] {subprocess.py:93} INFO - Compilation Error
[2023-06-23T15:10:47.753+0000] {subprocess.py:93} INFO -   dbt found two models with the name "ed_pipeline_logs".
[2023-06-23T15:10:47.753+0000] {subprocess.py:93} INFO - 
[2023-06-23T15:10:47.754+0000] {subprocess.py:93} INFO -   Since these resources have the same name, dbt will be unable to find the correct resource
[2023-06-23T15:10:47.754+0000] {subprocess.py:93} INFO -   when looking for ref("ed_pipeline_logs").
[2023-06-23T15:10:47.755+0000] {subprocess.py:93} INFO - 
[2023-06-23T15:10:47.755+0000] {subprocess.py:93} INFO -   To fix this, change the name of one of these resources:
[2023-06-23T15:10:47.756+0000] {subprocess.py:93} INFO -   - model.badge_5.ed_pipeline_logs (models/ed_pipeline_logs/target/compiled/badge_5/models/ed_pipeline_logs/ed_pipeline_logs.sql)
[2023-06-23T15:10:47.756+0000] {subprocess.py:93} INFO -   - model.badge_5.ed_pipeline_logs (models/ed_pipeline_logs/ed_pipeline_logs.sql)
[2023-06-23T15:10:48.328+0000] {subprocess.py:97} INFO - Command exited with return code 2
[2023-06-23T15:10:48.340+0000] {taskinstance.py:1824} ERROR - Task failed with exception
Traceback (most recent call last):
  File "/home/airflow/.local/lib/python3.7/site-packages/airflow/operators/bash.py", line 211, in execute
    f"Bash command failed. The command returned a non-zero exit code {result.exit_code}."
airflow.exceptions.AirflowException: Bash command failed. The command returned a non-zero exit code 2.
[2023-06-23T15:10:48.343+0000] {taskinstance.py:1350} INFO - Marking task as FAILED. dag_id=2_Test_Badge_5, task_id=test_create_stage, execution_date=20230623T151036, start_date=20230623T151037, end_date=20230623T151048
[2023-06-23T15:10:48.356+0000] {standard_task_runner.py:109} ERROR - Failed to execute job 39 for task test_create_stage (Bash command failed. The command returned a non-zero exit code 2.; 646)
[2023-06-23T15:10:48.442+0000] {local_task_job_runner.py:225} INFO - Task exited with return code 1
[2023-06-23T15:10:48.456+0000] {taskinstance.py:2651} INFO - 0 downstream tasks scheduled from follow-on schedule check
