[2023-06-27T14:18:11.642+0000] {logging_mixin.py:149} INFO - Changing /opt/***/logs/dag_id=2_Test_Badge_5_Setup/run_id=manual__2023-06-27T14:18:09.421834+00:00/task_id=load_seed_todl_once permission to 509
[2023-06-27T14:18:11.643+0000] {logging_mixin.py:149} INFO - Failed to change /opt/***/logs/dag_id=2_Test_Badge_5_Setup/run_id=manual__2023-06-27T14:18:09.421834+00:00/task_id=load_seed_todl_once permission to 509: [Errno 1] Operation not permitted: '/opt/***/logs/dag_id=2_Test_Badge_5_Setup/run_id=manual__2023-06-27T14:18:09.421834+00:00/task_id=load_seed_todl_once'
[2023-06-27T14:18:11.702+0000] {logging_mixin.py:149} INFO - Changing /opt/***/logs/dag_id=2_Test_Badge_5_Setup/run_id=manual__2023-06-27T14:18:09.421834+00:00/task_id=load_seed_todl_once permission to 509
[2023-06-27T14:18:11.735+0000] {logging_mixin.py:149} INFO - Failed to change /opt/***/logs/dag_id=2_Test_Badge_5_Setup/run_id=manual__2023-06-27T14:18:09.421834+00:00/task_id=load_seed_todl_once permission to 509: [Errno 1] Operation not permitted: '/opt/***/logs/dag_id=2_Test_Badge_5_Setup/run_id=manual__2023-06-27T14:18:09.421834+00:00/task_id=load_seed_todl_once'
[2023-06-27T14:18:11.940+0000] {taskinstance.py:1103} INFO - Dependencies all met for dep_context=non-requeueable deps ti=<TaskInstance: 2_Test_Badge_5_Setup.load_seed_todl_once manual__2023-06-27T14:18:09.421834+00:00 [queued]>
[2023-06-27T14:18:11.950+0000] {taskinstance.py:1103} INFO - Dependencies all met for dep_context=requeueable deps ti=<TaskInstance: 2_Test_Badge_5_Setup.load_seed_todl_once manual__2023-06-27T14:18:09.421834+00:00 [queued]>
[2023-06-27T14:18:11.951+0000] {taskinstance.py:1308} INFO - Starting attempt 1 of 1
[2023-06-27T14:18:11.967+0000] {taskinstance.py:1327} INFO - Executing <Task(BashOperator): load_seed_todl_once> on 2023-06-27 14:18:09.421834+00:00
[2023-06-27T14:18:11.972+0000] {standard_task_runner.py:57} INFO - Started process 103 to run task
[2023-06-27T14:18:11.977+0000] {standard_task_runner.py:84} INFO - Running: ['***', 'tasks', 'run', '2_Test_Badge_5_Setup', 'load_seed_todl_once', 'manual__2023-06-27T14:18:09.421834+00:00', '--job-id', '280', '--raw', '--subdir', 'DAGS_FOLDER/test.py', '--cfg-path', '/tmp/tmpz_v1vh0n']
[2023-06-27T14:18:11.980+0000] {standard_task_runner.py:85} INFO - Job 280: Subtask load_seed_todl_once
[2023-06-27T14:18:12.030+0000] {logging_mixin.py:149} INFO - Changing /opt/***/logs/dag_id=2_Test_Badge_5_Setup/run_id=manual__2023-06-27T14:18:09.421834+00:00/task_id=load_seed_todl_once permission to 509
[2023-06-27T14:18:12.031+0000] {logging_mixin.py:149} INFO - Failed to change /opt/***/logs/dag_id=2_Test_Badge_5_Setup/run_id=manual__2023-06-27T14:18:09.421834+00:00/task_id=load_seed_todl_once permission to 509: [Errno 1] Operation not permitted: '/opt/***/logs/dag_id=2_Test_Badge_5_Setup/run_id=manual__2023-06-27T14:18:09.421834+00:00/task_id=load_seed_todl_once'
[2023-06-27T14:18:12.034+0000] {task_command.py:410} INFO - Running <TaskInstance: 2_Test_Badge_5_Setup.load_seed_todl_once manual__2023-06-27T14:18:09.421834+00:00 [running]> on host eb22b15bae36
[2023-06-27T14:18:12.180+0000] {taskinstance.py:1547} INFO - Exporting env vars: AIRFLOW_CTX_DAG_OWNER='***' AIRFLOW_CTX_DAG_ID='2_Test_Badge_5_Setup' AIRFLOW_CTX_TASK_ID='load_seed_todl_once' AIRFLOW_CTX_EXECUTION_DATE='2023-06-27T14:18:09.421834+00:00' AIRFLOW_CTX_TRY_NUMBER='1' AIRFLOW_CTX_DAG_RUN_ID='manual__2023-06-27T14:18:09.421834+00:00'
[2023-06-27T14:18:12.184+0000] {subprocess.py:63} INFO - Tmp dir root location: 
 /tmp
[2023-06-27T14:18:12.185+0000] {subprocess.py:75} INFO - Running command: ['/bin/bash', '-c', 'cd /dbt && dbt seed --profiles-dir .']
[2023-06-27T14:18:12.195+0000] {subprocess.py:86} INFO - Output:
[2023-06-27T14:18:15.466+0000] {subprocess.py:93} INFO - [0m14:18:15  Running with dbt=1.5.1
[2023-06-27T14:18:18.696+0000] {subprocess.py:93} INFO - [0m14:18:18  Found 2 models, 0 tests, 0 snapshots, 0 analyses, 456 macros, 0 operations, 1 seed file, 0 sources, 0 exposures, 0 metrics, 0 groups
[2023-06-27T14:18:18.700+0000] {subprocess.py:93} INFO - [0m14:18:18
[2023-06-27T14:18:19.789+0000] {subprocess.py:93} INFO - [0m14:18:19  Concurrency: 200 threads (target='dev')
[2023-06-27T14:18:19.790+0000] {subprocess.py:93} INFO - [0m14:18:19
[2023-06-27T14:18:19.862+0000] {subprocess.py:93} INFO - [0m14:18:19  1 of 1 START seed file ***.time_of_day_lu .................................. [RUN]
[2023-06-27T14:18:19.900+0000] {subprocess.py:93} INFO - [0m14:18:19  [31mUnhandled error while executing [0m
[2023-06-27T14:18:19.901+0000] {subprocess.py:93} INFO - [Errno 2] No such file or directory: '/mnt/d/IPPON/Airflow/Project/Badge_Airflow/badge_5/seeds/time_of_day_lu.csv'
[2023-06-27T14:18:19.909+0000] {subprocess.py:93} INFO - [0m14:18:19  1 of 1 ERROR loading seed file ***.time_of_day_lu .......................... [[31mERROR[0m in 0.04s]
[2023-06-27T14:18:19.977+0000] {subprocess.py:93} INFO - [0m14:18:19
[2023-06-27T14:18:19.978+0000] {subprocess.py:93} INFO - [0m14:18:19  Finished running 1 seed in 0 hours 0 minutes and 1.28 seconds (1.28s).
[2023-06-27T14:18:20.009+0000] {subprocess.py:93} INFO - [0m14:18:20
[2023-06-27T14:18:20.010+0000] {subprocess.py:93} INFO - [0m14:18:20  [31mCompleted with 1 error and 0 warnings:[0m
[2023-06-27T14:18:20.011+0000] {subprocess.py:93} INFO - [0m14:18:20
[2023-06-27T14:18:20.013+0000] {subprocess.py:93} INFO - [0m14:18:20  [33m[Errno 2] No such file or directory: '/mnt/d/IPPON/Airflow/Project/Badge_Airflow/badge_5/seeds/time_of_day_lu.csv'[0m
[2023-06-27T14:18:20.014+0000] {subprocess.py:93} INFO - [0m14:18:20
[2023-06-27T14:18:20.016+0000] {subprocess.py:93} INFO - [0m14:18:20  Done. PASS=0 WARN=0 ERROR=1 SKIP=0 TOTAL=1
[2023-06-27T14:18:20.658+0000] {subprocess.py:97} INFO - Command exited with return code 1
[2023-06-27T14:18:20.671+0000] {taskinstance.py:1824} ERROR - Task failed with exception
Traceback (most recent call last):
  File "/home/airflow/.local/lib/python3.7/site-packages/airflow/operators/bash.py", line 211, in execute
    f"Bash command failed. The command returned a non-zero exit code {result.exit_code}."
airflow.exceptions.AirflowException: Bash command failed. The command returned a non-zero exit code 1.
[2023-06-27T14:18:20.676+0000] {taskinstance.py:1350} INFO - Marking task as FAILED. dag_id=2_Test_Badge_5_Setup, task_id=load_seed_todl_once, execution_date=20230627T141809, start_date=20230627T141811, end_date=20230627T141820
[2023-06-27T14:18:20.691+0000] {standard_task_runner.py:109} ERROR - Failed to execute job 280 for task load_seed_todl_once (Bash command failed. The command returned a non-zero exit code 1.; 103)
[2023-06-27T14:18:20.732+0000] {local_task_job_runner.py:225} INFO - Task exited with return code 1
[2023-06-27T14:18:20.761+0000] {taskinstance.py:2651} INFO - 0 downstream tasks scheduled from follow-on schedule check
