[2023-06-27T09:23:32.441+0000] {logging_mixin.py:149} INFO - Changing /opt/***/logs/dag_id=2_Test_Badge_5_Loop/run_id=manual__2023-06-27T09:23:31.336193+00:00/task_id=create_select permission to 509
[2023-06-27T09:23:32.442+0000] {logging_mixin.py:149} INFO - Failed to change /opt/***/logs/dag_id=2_Test_Badge_5_Loop/run_id=manual__2023-06-27T09:23:31.336193+00:00/task_id=create_select permission to 509: [Errno 1] Operation not permitted: '/opt/***/logs/dag_id=2_Test_Badge_5_Loop/run_id=manual__2023-06-27T09:23:31.336193+00:00/task_id=create_select'
[2023-06-27T09:23:32.471+0000] {logging_mixin.py:149} INFO - Changing /opt/***/logs/dag_id=2_Test_Badge_5_Loop/run_id=manual__2023-06-27T09:23:31.336193+00:00/task_id=create_select permission to 509
[2023-06-27T09:23:32.472+0000] {logging_mixin.py:149} INFO - Failed to change /opt/***/logs/dag_id=2_Test_Badge_5_Loop/run_id=manual__2023-06-27T09:23:31.336193+00:00/task_id=create_select permission to 509: [Errno 1] Operation not permitted: '/opt/***/logs/dag_id=2_Test_Badge_5_Loop/run_id=manual__2023-06-27T09:23:31.336193+00:00/task_id=create_select'
[2023-06-27T09:23:32.629+0000] {taskinstance.py:1103} INFO - Dependencies all met for dep_context=non-requeueable deps ti=<TaskInstance: 2_Test_Badge_5_Loop.create_select manual__2023-06-27T09:23:31.336193+00:00 [queued]>
[2023-06-27T09:23:32.638+0000] {taskinstance.py:1103} INFO - Dependencies all met for dep_context=requeueable deps ti=<TaskInstance: 2_Test_Badge_5_Loop.create_select manual__2023-06-27T09:23:31.336193+00:00 [queued]>
[2023-06-27T09:23:32.639+0000] {taskinstance.py:1308} INFO - Starting attempt 1 of 1
[2023-06-27T09:23:32.658+0000] {taskinstance.py:1327} INFO - Executing <Task(BashOperator): create_select> on 2023-06-27 09:23:31.336193+00:00
[2023-06-27T09:23:32.664+0000] {standard_task_runner.py:57} INFO - Started process 13962 to run task
[2023-06-27T09:23:32.668+0000] {standard_task_runner.py:84} INFO - Running: ['***', 'tasks', 'run', '2_Test_Badge_5_Loop', 'create_select', 'manual__2023-06-27T09:23:31.336193+00:00', '--job-id', '209', '--raw', '--subdir', 'DAGS_FOLDER/test.py', '--cfg-path', '/tmp/tmpsng_dksu']
[2023-06-27T09:23:32.671+0000] {standard_task_runner.py:85} INFO - Job 209: Subtask create_select
[2023-06-27T09:23:32.721+0000] {logging_mixin.py:149} INFO - Changing /opt/***/logs/dag_id=2_Test_Badge_5_Loop/run_id=manual__2023-06-27T09:23:31.336193+00:00/task_id=create_select permission to 509
[2023-06-27T09:23:32.722+0000] {logging_mixin.py:149} INFO - Failed to change /opt/***/logs/dag_id=2_Test_Badge_5_Loop/run_id=manual__2023-06-27T09:23:31.336193+00:00/task_id=create_select permission to 509: [Errno 1] Operation not permitted: '/opt/***/logs/dag_id=2_Test_Badge_5_Loop/run_id=manual__2023-06-27T09:23:31.336193+00:00/task_id=create_select'
[2023-06-27T09:23:32.725+0000] {task_command.py:410} INFO - Running <TaskInstance: 2_Test_Badge_5_Loop.create_select manual__2023-06-27T09:23:31.336193+00:00 [running]> on host 4d37da440d5c
[2023-06-27T09:23:32.835+0000] {taskinstance.py:1547} INFO - Exporting env vars: AIRFLOW_CTX_DAG_OWNER='***' AIRFLOW_CTX_DAG_ID='2_Test_Badge_5_Loop' AIRFLOW_CTX_TASK_ID='create_select' AIRFLOW_CTX_EXECUTION_DATE='2023-06-27T09:23:31.336193+00:00' AIRFLOW_CTX_TRY_NUMBER='1' AIRFLOW_CTX_DAG_RUN_ID='manual__2023-06-27T09:23:31.336193+00:00'
[2023-06-27T09:23:32.837+0000] {subprocess.py:63} INFO - Tmp dir root location: 
 /tmp
[2023-06-27T09:23:32.838+0000] {subprocess.py:75} INFO - Running command: ['/bin/bash', '-c', 'cd /dbt && dbt run --model select']
[2023-06-27T09:23:32.847+0000] {subprocess.py:86} INFO - Output:
[2023-06-27T09:23:35.640+0000] {subprocess.py:93} INFO - [0m09:23:35  Running with dbt=1.5.1
[2023-06-27T09:23:42.422+0000] {subprocess.py:93} INFO - [0m09:23:42  [[33mWARNING[0m]: Configuration paths exist in your dbt_project.yml file which do not apply to any resources.
[2023-06-27T09:23:42.423+0000] {subprocess.py:93} INFO - There are 2 unused configuration paths:
[2023-06-27T09:23:42.423+0000] {subprocess.py:93} INFO - - models.badge_5.create_stage
[2023-06-27T09:23:42.424+0000] {subprocess.py:93} INFO - - models.badge_5.time_of_day
[2023-06-27T09:23:42.493+0000] {subprocess.py:93} INFO - [0m09:23:42  Found 2 models, 0 tests, 0 snapshots, 0 analyses, 455 macros, 0 operations, 1 seed file, 0 sources, 0 exposures, 0 metrics, 0 groups
[2023-06-27T09:23:42.496+0000] {subprocess.py:93} INFO - [0m09:23:42
[2023-06-27T09:23:43.772+0000] {subprocess.py:93} INFO - [0m09:23:43  Concurrency: 200 threads (target='dev')
[2023-06-27T09:23:43.774+0000] {subprocess.py:93} INFO - [0m09:23:43
[2023-06-27T09:23:43.830+0000] {subprocess.py:93} INFO - [0m09:23:43  1 of 1 START sql table model ***.select .................................... [RUN]
[2023-06-27T09:23:44.494+0000] {subprocess.py:93} INFO - [0m09:23:44  1 of 1 ERROR creating sql table model ***.select ........................... [[31mERROR[0m in 0.66s]
[2023-06-27T09:23:44.559+0000] {subprocess.py:93} INFO - [0m09:23:44
[2023-06-27T09:23:44.560+0000] {subprocess.py:93} INFO - [0m09:23:44  Finished running 1 table model in 0 hours 0 minutes and 2.06 seconds (2.06s).
[2023-06-27T09:23:44.621+0000] {subprocess.py:93} INFO - [0m09:23:44
[2023-06-27T09:23:44.622+0000] {subprocess.py:93} INFO - [0m09:23:44  [31mCompleted with 1 error and 0 warnings:[0m
[2023-06-27T09:23:44.623+0000] {subprocess.py:93} INFO - [0m09:23:44
[2023-06-27T09:23:44.624+0000] {subprocess.py:93} INFO - [0m09:23:44  [33mDatabase Error in model select (models/select/select.sql)[0m
[2023-06-27T09:23:44.626+0000] {subprocess.py:93} INFO - [0m09:23:44    001003 (42000): SQL compilation error:
[2023-06-27T09:23:44.627+0000] {subprocess.py:93} INFO - [0m09:23:44    syntax error line 1 at position 52 unexpected '.'.
[2023-06-27T09:23:44.628+0000] {subprocess.py:93} INFO - [0m09:23:44    compiled Code at target/run/badge_5/models/select/select.sql
[2023-06-27T09:23:44.629+0000] {subprocess.py:93} INFO - [0m09:23:44
[2023-06-27T09:23:44.630+0000] {subprocess.py:93} INFO - [0m09:23:44  Done. PASS=0 WARN=0 ERROR=1 SKIP=0 TOTAL=1
[2023-06-27T09:23:45.229+0000] {subprocess.py:97} INFO - Command exited with return code 1
[2023-06-27T09:23:45.240+0000] {taskinstance.py:1824} ERROR - Task failed with exception
Traceback (most recent call last):
  File "/home/airflow/.local/lib/python3.7/site-packages/airflow/operators/bash.py", line 211, in execute
    f"Bash command failed. The command returned a non-zero exit code {result.exit_code}."
airflow.exceptions.AirflowException: Bash command failed. The command returned a non-zero exit code 1.
[2023-06-27T09:23:45.244+0000] {taskinstance.py:1350} INFO - Marking task as FAILED. dag_id=2_Test_Badge_5_Loop, task_id=create_select, execution_date=20230627T092331, start_date=20230627T092332, end_date=20230627T092345
[2023-06-27T09:23:45.256+0000] {standard_task_runner.py:109} ERROR - Failed to execute job 209 for task create_select (Bash command failed. The command returned a non-zero exit code 1.; 13962)
[2023-06-27T09:23:45.394+0000] {local_task_job_runner.py:225} INFO - Task exited with return code 1
[2023-06-27T09:23:45.409+0000] {taskinstance.py:2651} INFO - 0 downstream tasks scheduled from follow-on schedule check
